[2023-06-20 21:17:01,098] decorator.py[line:24] ERROR Traceback (most recent call last):
  File "/Users/chenxutong/Documents/file/work/workspace/sdtest/utils/decorator.py", line 22, in wrapper
    return func(*args, **kargs)
  File "/Users/chenxutong/Documents/file/work/workspace/sdtest/web/python_template_server.py", line 116, in submit_task
    res = dbm.query(sql_check)
  File "/Users/chenxutong/Documents/file/work/workspace/sdtest/utils/db_manager.py", line 43, in query
    self.cursor.execute(sql)
  File "/Users/chenxutong/anaconda3/lib/python3.7/site-packages/pymysql/cursors.py", line 158, in execute
    result = self._query(query)
  File "/Users/chenxutong/anaconda3/lib/python3.7/site-packages/pymysql/cursors.py", line 325, in _query
    conn.query(q)
  File "/Users/chenxutong/anaconda3/lib/python3.7/site-packages/pymysql/connections.py", line 549, in query
    self._affected_rows = self._read_query_result(unbuffered=unbuffered)
  File "/Users/chenxutong/anaconda3/lib/python3.7/site-packages/pymysql/connections.py", line 779, in _read_query_result
    result.read()
  File "/Users/chenxutong/anaconda3/lib/python3.7/site-packages/pymysql/connections.py", line 1157, in read
    first_packet = self.connection._read_packet()
  File "/Users/chenxutong/anaconda3/lib/python3.7/site-packages/pymysql/connections.py", line 729, in _read_packet
    packet.raise_for_error()
  File "/Users/chenxutong/anaconda3/lib/python3.7/site-packages/pymysql/protocol.py", line 221, in raise_for_error
    err.raise_mysql_exception(self._data)
  File "/Users/chenxutong/anaconda3/lib/python3.7/site-packages/pymysql/err.py", line 143, in raise_mysql_exception
    raise errorclass(errno, errval)
pymysql.err.OperationalError: (1054, "Unknown column 'order_time' in 'where clause'")

[2023-06-20 21:30:42,208] decorator.py[line:24] ERROR Traceback (most recent call last):
  File "/Users/chenxutong/Documents/file/work/workspace/sdtest/utils/decorator.py", line 22, in wrapper
    return func(*args, **kargs)
  File "/Users/chenxutong/Documents/file/work/workspace/sdtest/web/python_template_server.py", line 127, in submit_task
    check_username("aaa")
  File "/Users/chenxutong/Documents/file/work/workspace/sdtest/web/python_template_server.py", line 111, in check_username
    res1 = dbm.query(sql_check1)
  File "/Users/chenxutong/Documents/file/work/workspace/sdtest/utils/db_manager.py", line 43, in query
    self.cursor.execute(sql)
  File "/Users/chenxutong/anaconda3/lib/python3.7/site-packages/pymysql/cursors.py", line 158, in execute
    result = self._query(query)
  File "/Users/chenxutong/anaconda3/lib/python3.7/site-packages/pymysql/cursors.py", line 325, in _query
    conn.query(q)
  File "/Users/chenxutong/anaconda3/lib/python3.7/site-packages/pymysql/connections.py", line 549, in query
    self._affected_rows = self._read_query_result(unbuffered=unbuffered)
  File "/Users/chenxutong/anaconda3/lib/python3.7/site-packages/pymysql/connections.py", line 779, in _read_query_result
    result.read()
  File "/Users/chenxutong/anaconda3/lib/python3.7/site-packages/pymysql/connections.py", line 1157, in read
    first_packet = self.connection._read_packet()
  File "/Users/chenxutong/anaconda3/lib/python3.7/site-packages/pymysql/connections.py", line 729, in _read_packet
    packet.raise_for_error()
  File "/Users/chenxutong/anaconda3/lib/python3.7/site-packages/pymysql/protocol.py", line 221, in raise_for_error
    err.raise_mysql_exception(self._data)
  File "/Users/chenxutong/anaconda3/lib/python3.7/site-packages/pymysql/err.py", line 143, in raise_mysql_exception
    raise errorclass(errno, errval)
pymysql.err.ProgrammingError: (1146, "Table 'fangdao_image_server.wp_users' doesn't exist")

[2023-06-20 22:04:33,271] decorator.py[line:24] ERROR Traceback (most recent call last):
  File "/Users/chenxutong/Documents/file/work/workspace/sdtest/utils/decorator.py", line 22, in wrapper
    return func(*args, **kargs)
  File "/Users/chenxutong/Documents/file/work/workspace/sdtest/web/python_template_server.py", line 134, in submit_task
    isOk, msg = check_username(user_name)
TypeError: cannot unpack non-iterable bool object

[2023-06-20 22:04:39,465] decorator.py[line:24] ERROR Traceback (most recent call last):
  File "/Users/chenxutong/Documents/file/work/workspace/sdtest/utils/decorator.py", line 22, in wrapper
    return func(*args, **kargs)
  File "/Users/chenxutong/Documents/file/work/workspace/sdtest/web/python_template_server.py", line 134, in submit_task
    isOk, msg = check_username(user_name)
TypeError: cannot unpack non-iterable bool object

[2023-06-20 22:04:42,194] decorator.py[line:24] ERROR Traceback (most recent call last):
  File "/Users/chenxutong/Documents/file/work/workspace/sdtest/utils/decorator.py", line 22, in wrapper
    return func(*args, **kargs)
  File "/Users/chenxutong/Documents/file/work/workspace/sdtest/web/python_template_server.py", line 134, in submit_task
    isOk, msg = check_username(user_name)
TypeError: cannot unpack non-iterable bool object

[2023-06-20 22:12:39,208] decorator.py[line:24] ERROR Traceback (most recent call last):
  File "/Users/chenxutong/Documents/file/work/workspace/sdtest/utils/decorator.py", line 22, in wrapper
    return func(*args, **kargs)
  File "/Users/chenxutong/Documents/file/work/workspace/sdtest/web/python_template_server.py", line 135, in submit_task
    isOk, msg = check_username(user_name)
TypeError: cannot unpack non-iterable bool object

[2023-06-20 22:14:56,850] decorator.py[line:24] ERROR Traceback (most recent call last):
  File "/Users/chenxutong/Documents/file/work/workspace/sdtest/utils/decorator.py", line 22, in wrapper
    return func(*args, **kargs)
  File "/Users/chenxutong/Documents/file/work/workspace/sdtest/web/python_template_server.py", line 135, in submit_task
    isOk, msg = check_username(user_name)
TypeError: cannot unpack non-iterable bool object

[2023-06-20 22:16:38,361] decorator.py[line:24] ERROR Traceback (most recent call last):
  File "/Users/chenxutong/Documents/file/work/workspace/sdtest/utils/decorator.py", line 22, in wrapper
    return func(*args, **kargs)
  File "/Users/chenxutong/Documents/file/work/workspace/sdtest/web/python_template_server.py", line 135, in submit_task
    isOk, msg = check_username(user_name)
TypeError: cannot unpack non-iterable bool object

[2023-06-20 22:16:48,372] decorator.py[line:24] ERROR Traceback (most recent call last):
  File "/Users/chenxutong/Documents/file/work/workspace/sdtest/utils/decorator.py", line 22, in wrapper
    return func(*args, **kargs)
  File "/Users/chenxutong/Documents/file/work/workspace/sdtest/web/python_template_server.py", line 135, in submit_task
    isOk, msg = check_username(user_name)
TypeError: cannot unpack non-iterable bool object

