[2023-06-21 11:07:38,388] decorator.py[line:24] ERROR Traceback (most recent call last):
  File "/root/ai/sdtest/utils/decorator.py", line 22, in wrapper
    return func(*args, **kargs)
  File "/root/ai/sdtest/web/python_template_server.py", line 132, in submit_task
    isOk, msg = check_username(user_name)
NameError: name 'user_name' is not defined

[2023-06-21 11:09:42,847] decorator.py[line:24] ERROR Traceback (most recent call last):
  File "/root/ai/sdtest/utils/decorator.py", line 22, in wrapper
    return func(*args, **kargs)
  File "/root/ai/sdtest/web/python_template_server.py", line 132, in submit_task
    isOk, msg = check_username(user_name)
NameError: name 'user_name' is not defined

[2023-06-21 11:10:10,080] decorator.py[line:24] ERROR Traceback (most recent call last):
  File "/root/ai/sdtest/utils/decorator.py", line 22, in wrapper
    return func(*args, **kargs)
  File "/root/ai/sdtest/web/python_template_server.py", line 132, in submit_task
    isOk, msg = check_username(user_name)
NameError: name 'user_name' is not defined

[2023-06-21 11:13:46,610] decorator.py[line:24] ERROR Traceback (most recent call last):
  File "/root/ai/sdtest/utils/decorator.py", line 22, in wrapper
    return func(*args, **kargs)
  File "/root/ai/sdtest/web/python_template_server.py", line 132, in submit_task
    isOk, msg = check_username(user_name)
NameError: name 'user_name' is not defined

[2023-06-21 11:17:44,056] decorator.py[line:24] ERROR Traceback (most recent call last):
  File "/root/ai/sdtest/utils/decorator.py", line 22, in wrapper
    return func(*args, **kargs)
  File "/root/ai/sdtest/web/python_template_server.py", line 132, in submit_task
    isOk, msg = check_username(user_name)
NameError: name 'user_name' is not defined

[2023-06-21 11:26:41,418] decorator.py[line:24] ERROR Traceback (most recent call last):
  File "/root/ai/sdtest/utils/decorator.py", line 22, in wrapper
    return func(*args, **kargs)
  File "/root/ai/sdtest/web/python_template_server.py", line 143, in submit_task
    dbm.insert(sql, data)
  File "/root/ai/sdtest/utils/db_manager.py", line 72, in insert
    self.cursor.executemany(sql, data)
  File "/usr/local/lib/python3.10/dist-packages/pymysql/cursors.py", line 187, in executemany
    return self._do_execute_many(
  File "/usr/local/lib/python3.10/dist-packages/pymysql/cursors.py", line 225, in _do_execute_many
    rows += self.execute(sql + postfix)
  File "/usr/local/lib/python3.10/dist-packages/pymysql/cursors.py", line 158, in execute
    result = self._query(query)
  File "/usr/local/lib/python3.10/dist-packages/pymysql/cursors.py", line 325, in _query
    conn.query(q)
  File "/usr/local/lib/python3.10/dist-packages/pymysql/connections.py", line 549, in query
    self._affected_rows = self._read_query_result(unbuffered=unbuffered)
  File "/usr/local/lib/python3.10/dist-packages/pymysql/connections.py", line 779, in _read_query_result
    result.read()
  File "/usr/local/lib/python3.10/dist-packages/pymysql/connections.py", line 1157, in read
    first_packet = self.connection._read_packet()
  File "/usr/local/lib/python3.10/dist-packages/pymysql/connections.py", line 729, in _read_packet
    packet.raise_for_error()
  File "/usr/local/lib/python3.10/dist-packages/pymysql/protocol.py", line 221, in raise_for_error
    err.raise_mysql_exception(self._data)
  File "/usr/local/lib/python3.10/dist-packages/pymysql/err.py", line 143, in raise_mysql_exception
    raise errorclass(errno, errval)
pymysql.err.DataError: (1406, "Data too long for column 'param' at row 1")

[2023-06-21 11:48:02,894] decorator.py[line:24] ERROR Traceback (most recent call last):
  File "/root/ai/sdtest/utils/decorator.py", line 22, in wrapper
    return func(*args, **kargs)
  File "/root/ai/sdtest/web/python_template_server.py", line 143, in submit_task
    dbm.insert(sql, data)
  File "/root/ai/sdtest/utils/db_manager.py", line 72, in insert
    self.cursor.executemany(sql, data)
  File "/usr/local/lib/python3.10/dist-packages/pymysql/cursors.py", line 187, in executemany
    return self._do_execute_many(
  File "/usr/local/lib/python3.10/dist-packages/pymysql/cursors.py", line 225, in _do_execute_many
    rows += self.execute(sql + postfix)
  File "/usr/local/lib/python3.10/dist-packages/pymysql/cursors.py", line 158, in execute
    result = self._query(query)
  File "/usr/local/lib/python3.10/dist-packages/pymysql/cursors.py", line 325, in _query
    conn.query(q)
  File "/usr/local/lib/python3.10/dist-packages/pymysql/connections.py", line 549, in query
    self._affected_rows = self._read_query_result(unbuffered=unbuffered)
  File "/usr/local/lib/python3.10/dist-packages/pymysql/connections.py", line 779, in _read_query_result
    result.read()
  File "/usr/local/lib/python3.10/dist-packages/pymysql/connections.py", line 1157, in read
    first_packet = self.connection._read_packet()
  File "/usr/local/lib/python3.10/dist-packages/pymysql/connections.py", line 729, in _read_packet
    packet.raise_for_error()
  File "/usr/local/lib/python3.10/dist-packages/pymysql/protocol.py", line 221, in raise_for_error
    err.raise_mysql_exception(self._data)
  File "/usr/local/lib/python3.10/dist-packages/pymysql/err.py", line 143, in raise_mysql_exception
    raise errorclass(errno, errval)
pymysql.err.DataError: (1406, "Data too long for column 'param' at row 1")

[2023-06-21 11:56:25,992] decorator.py[line:24] ERROR Traceback (most recent call last):
  File "/root/ai/sdtest/utils/decorator.py", line 22, in wrapper
    return func(*args, **kargs)
  File "/root/ai/sdtest/web/python_template_server.py", line 143, in submit_task
    dbm.insert(sql, data)
  File "/root/ai/sdtest/utils/db_manager.py", line 72, in insert
    self.cursor.executemany(sql, data)
  File "/usr/local/lib/python3.10/dist-packages/pymysql/cursors.py", line 187, in executemany
    return self._do_execute_many(
  File "/usr/local/lib/python3.10/dist-packages/pymysql/cursors.py", line 225, in _do_execute_many
    rows += self.execute(sql + postfix)
  File "/usr/local/lib/python3.10/dist-packages/pymysql/cursors.py", line 158, in execute
    result = self._query(query)
  File "/usr/local/lib/python3.10/dist-packages/pymysql/cursors.py", line 325, in _query
    conn.query(q)
  File "/usr/local/lib/python3.10/dist-packages/pymysql/connections.py", line 549, in query
    self._affected_rows = self._read_query_result(unbuffered=unbuffered)
  File "/usr/local/lib/python3.10/dist-packages/pymysql/connections.py", line 779, in _read_query_result
    result.read()
  File "/usr/local/lib/python3.10/dist-packages/pymysql/connections.py", line 1157, in read
    first_packet = self.connection._read_packet()
  File "/usr/local/lib/python3.10/dist-packages/pymysql/connections.py", line 729, in _read_packet
    packet.raise_for_error()
  File "/usr/local/lib/python3.10/dist-packages/pymysql/protocol.py", line 221, in raise_for_error
    err.raise_mysql_exception(self._data)
  File "/usr/local/lib/python3.10/dist-packages/pymysql/err.py", line 143, in raise_mysql_exception
    raise errorclass(errno, errval)
pymysql.err.DataError: (1406, "Data too long for column 'param' at row 1")

